Workbook

Sheet Sheet1
A1: 年 | B1: 2026
A2: 月 | B2: (多项)
A3: 日 | B3: (全部)
A4: 费用类型 | B4: 商务扣款
A6: 发出部门 | B6: 计数项:接收部门 | C6: 求和项:费用金额 | D6: 求和项:费用对应吨数
A7: 珠三角经营部 | B7: 105 | C7: 1412076.2 | D7: 93548.52
A8: 粤西经营部 | B8: 27 | C8: 232206.34 | D8: 20856.46
A9: 广西经营部 | B9: 28 | C9: 202600.82 | D9: 22235.531
A10: 福建经营部 | B10: 66 | C10: 899767.99 | D10: 106154.74
A11: 海南经营部 | B11: 5 | C11: 39266.2 | D11: 2130.36
A12: 总计 | B12: 231 | C12: 2785917.5 | D12: 244925.61
A14: 经营部 | B14: 商扣笔数 | C14: 商扣金额（万元） | D14: 商扣吨数（万吨） | E14: 单吨商扣 （元/吨） | F14: 累计结算量（万吨） | G14: 商扣均摊至结算量（元/吨） | H14: 商扣数量占结算数量比例
A15: 珠三角 | B15: 105 | C15: 141.20762 | D15: 9.354852 | E15: =C15/D15 -> 15.094586 | F15: 110.36 | G15: =C15/F15 -> 1.2795181 | H15: =D15/F15 -> 0.084766691
A16: 粤西 | B16: 27 | C16: 23.220634 | D16: 2.085646 | E16: =C16/D16 -> 11.133545 | F16: 77.93 | G16: =C16/F16 -> 0.29796784 | H16: =D16/F16 -> 0.026763069
A17: 广西 | B17: 28 | C17: 20.260082 | D17: 2.2235531 | E17: =C17/D17 -> 9.11158 | F17: 51.65 | G17: =C17/F17 -> 0.39225715 | H17: =D17/F17 -> 0.043050399
A18: 福建 | B18: 66 | C18: 89.976799 | D18: 10.615474 | E18: =C18/D18 -> 8.4760038 | F18: 59.37 | G18: =C18/F18 -> 1.5155263 | H18: =D18/F18 -> 0.17880199
A19: 海南 | B19: 5 | C19: 3.92662 | D19: 0.213036 | E19: =C19/D19 -> 18.43172 | F19: 43.73 | G19: =C19/F19 -> 0.089792362 | H19: =D19/F19 -> 0.0048716213
A20: 总计 | B20: 231 | C20: 278.59175 | D20: 24.492561 | E20: =C20/D20 -> 11.374546 | F20: 343.04 | G20: =C20/F20 -> 0.81212615 | H20: =D20/F20 -> 0.071398558
C21: 10000
A22: 年 | B22: 2026 | C22: =C20-264.19 -> 14.401754
A23: 月 | B23: (多项)
A24: 费用类型 | B24: (全部)
A25: 发出部门 | B25: (多项)
A27: 扣款原因-清洗 | B27: 求和项:费用金额 | C27: 求和项:费用对应吨数 | F27: 扣款原因 | G27: 扣款金额（元） | H27: 占比
A28: 杂质 | B28: 1332384.7 | C28: 131575.95 | F28: 杂质 | G28: 1332384.7 | H28: =G28/$G$37 -> 0.47825706
A29: 水分 | B29: 804044.5 | C29: 70629.11 | F29: 水分 | G29: 804044.5 | H29: =G29/$G$37 -> 0.2886103
A30: 销售额外费用 | B30: 248896.05 | C30: 10349.282 | F30: 销售额外费用 | G30: 248896.05 | H30: =G30/$G$37 -> 0.089340781
A31: 霉变 | B31: 194483.72 | C31: 23431.145 | F31: 霉变 | G31: 194483.72 | H31: =G31/$G$37 -> 0.069809575
A32: 毒素 | B32: 104388.11 | C32: 7967.19 | F32: 毒素 | G32: 104388.11 | H32: =G32/$G$37 -> 0.037469921
A33: 短重 | B33: 48519.425 | C33: 20.04 | F33: 短重 | G33: 48519.425 | H33: =G33/$G$37 -> 0.017415959
A34: 热损伤 | B34: 45000 | C34: 446.5 | F34: 热损伤 | G34: 45000 | H34: =G34/$G$37 -> 0.016152668
A35: 不完善粒 | B35: 4309.1 | C35: 506.4 | F35: 不完善粒 | G35: 4309.1 | H35: =G35/$G$37 -> 0.0015467436
A36: 容重 | B36: 3891.9 | F36: 容重 | G36: 3891.9 | H36: =G36/$G$37 -> 0.0013969904
A37: 总计 | B37: 2785917.5 | C37: 244925.61 | F37: 总计 | G37: 2785917.5 | H37: =G37/$G$37 -> 1

Sheet 流程
A1: 联系单编号 | B1: 费用发生时间 | C1: 费用申请时间 | D1: 费用类型 | E1: 主题 | F1: 内容 | G1: 销售溢价是否覆盖扣款费用 | H1: 费用原因分类 | I1: 费用金额 | J1: 费用对应吨数 | K1: 费用对应大船名 | L1: 费用对应销售合同号 | M1: 发出部门 | N1: 接收部门 | O1: 发起人 | P1: 复核人1 | Q1: 复核人2 | R1: 复核人3 | S1: 复核人4 | T1: 复核人5 | U1: 费用最终承担方 | V1: 承担方名称/对应合同号 | W1: 复核结果备注 | X1: 扣款原因-清洗 | Y1: 年 | Z1: 月 | AA1: 日
A2: FJSWKK250529 | B2: 45752 | C2: 45782 | D2: 商务扣款 | E2: 关于福建省邵武市华龙饲料有限公司商务扣款说明 | F2: 兹有我司与福建省邵武华龙饲料有限公司签订《粮食销售合同》，合同号：YMFJFZ250015，合同数量3000吨，单价2240元/吨，截止2025年4月5日接货完毕。该合同提货2987.12吨，其中3月26日提货6车共计209.97吨，到货检测指标较差（杂质1.6%，霉变3.6%），经双方协商一致，退货转扣款接收，扣款10元/吨共计2099.7元，折合合同扣款0.7元/吨。 以上扣款，对应内部发运散船航安顺/2507，是否可行，请领导批示。 | H2: 质量问题（霉变、霉味、生虫等） | I2: 2099.7 | J2: 209.97 | M2: 福建经营部 | N2: 饲料原料部、风险管理部、财务部 | O2: 林玉婷 | P2: 福建经营部 | Q2: 大区品种线 | U2: 供应商 | Y2: =YEAR(C2) -> 2025 | Z2: =MONTH(C2) -> 5 | AA2: =DAY(C2) -> 5
B3: 5/13-5/15 | C3: 45817 | D3: 商务扣款 | E3: JZXYMGXXJ250003广西福祺保毒素箱子毒素超标扣款说明 | F3: 该批保毒素箱子21个，总计554.97吨，计划交付广西福祺饲料有限公司保毒素合同（合同号：JZXYMGXXJ250003），4月21日和4月25日从北方发出，5月3日至5月8日抵达贵港港（运单号：AUVTNTW250238777、ASNCLTL250258834），计划号YHSZ-25-032021。5月13日至5月15日全部提完。到厂检测毒素超标，7个箱子毒素指标在1100-1300ppb之间，14个箱子毒素指标在1400-1900ppb之间。我部及时与玉米品种线联系并向大区反映情况，后经大区协调，现场取样邮至北良港检测公司董乾仕复检，四个集装箱（ATHU1009372、ATHU1078877、FBIU0022667、FBIU0003991）分两个样品毒素检测结果值为1491ppb和1729ppb。下游客户要求商扣50元/吨，经我司协商最终扣20元/吨，总计11099.4元。 | H3: 品质不达标（容重、水分、毒素、蛋白等） | I3: 11099.4 | J3: 554.97 | L3: JZXYMGXXJ250003 | M3: 广西经营部 | O3: 侯霄 | P3: 广西经营部 | Q3: 大区品种线 | Y3: =YEAR(C3) -> 2025 | Z3: =MONTH(C3) -> 6 | AA3: =DAY(C3) -> 9
B4: 2025/5/17、6/2 | C4: 45826 | D4: 商务扣款 | E4: 关于龙岩华龙扣款说明 | F4: 我司与福建省龙岩市华龙饲料有限公司于2025年05月09日签署生效的《粮食销售合同》（合同编号：JZXYMFJZZ250004)，合同数量480吨，合同单价2420元/吨，截止至2025年06月04日，该合同累计提货471.075吨，客户于2025年5月17日接收玉米，检测呕吐毒素超标；检测容重未达标，合计产生扣款2704.76元，整批次提货471.075吨，折单吨扣款5.74元/吨 | H4: 品质不达标（容重、水分、毒素、蛋白等） | I4: 2704.76 | J4: 471.075 | M4: 福建经营部 | N4: 饲料原料部 | O4: 陈静文 | P4: 福建经营部 | Q4: 大区品种线 | Y4: =YEAR(C4) -> 2025 | Z4: =MONTH(C4) -> 6 | AA4: =DAY(C4) -> 18
B5: 2025/5/16、6/4 | C5: 45826 | D5: 商务扣款 | E5: 关于龙岩鑫华港饲料有限公司扣款说明 | F5: 我司与龙岩鑫华港饲料有限公司于2025年05月09日签署生效的《粮食销售合同》（合同编号：JZXYMFJZZ250005)，合同数量420吨，合同单价2420元/吨，截止至2025年05月20日，该合同累计提货414.4吨，检测有呕吐毒素超标；检测容重未达标，以上情况合计产生扣款2204.80元，整批次提货414.4吨，折单吨扣款5.32元/吨 | H5: 品质不达标（容重、水分、毒素、蛋白等） | I5: 2204.8 | J5: 414.4 | M5: 福建经营部 | N5: 饲料原料部 | O5: 陈静文 | P5: 福建经营部 | Q5: 大区品种线 | Y5: =YEAR(C5) -> 2025 | Z5: =MONTH(C5) -> 6 | AA5: =DAY(C5) -> 18
B6: 45811 | C6: 45826 | D6: 商务扣款 | E6: 关于武平鑫龙港饲料有限公司扣款说明 | F6: 我司与武平鑫龙港饲料有限公司于2025年05月09日签署生效的《粮食销售合同》（合同编号：JZXYMFJZZ250006)，合同数量220吨，合同单价2420元/吨，截止至2025年05月18日，该合同累计提货221.905吨，检测容重未达标，合计扣款1071.40元，整批次提货221.905吨，折单吨扣款4.83元/吨 | H6: 品质不达标（容重、水分、毒素、蛋白等） | I6: 1071.4 | J6: 221.905 | M6: 福建经营部 | N6: 饲料原料部 | O6: 陈静文 | P6: 福建经营部 | Q6: 大区品种线 | Y6: =YEAR(C6) -> 2025 | Z6: =MONTH(C6) -> 6 | AA6: =DAY(C6) -> 18
A7: JZXYMFJZZ250004-lxd01 | B7: 45866 | C7: 45866 | D7: 商务扣款 | E7: 福建省龙岩市华龙饲料有限公司 | I7: 11255 | J7: 11255 | K7: 玉米出险对应扣款 | L7: JZXYMFJZZ250004 | M7: 福建经营部 | N7: 饲料原料部 | O7: 陈静文 | P7: 福建经营部 | Q7: 大区品种线 | Y7: =YEAR(C7) -> 2025 | Z7: =MONTH(C7) -> 7 | AA7: =DAY(C7) -> 28
A8: YMFJZZ250152-lxd01 | B8: 45880 | C8: 45880 | D8: 商务扣款 | E8: 双胞胎（集团）股份有限公司 | I8: 1782 | J8: 1782 | K8: 呕吐毒素超标 | L8: YMFJZZ250152 | M8: 福建经营部 | N8: 饲料原料部 | O8: 陈静文 | P8: 福建经营部 | Q8: 大区品种线 | Y8: =YEAR(C8) -> 2025 | Z8: =MONTH(C8) -> 8 | AA8: =DAY(C8) -> 11
A9: YMFJZZ250142-lxd01 | B9: 45889 | C9: 45889 | D9: 商务扣款 | E9: 漳州温氏农牧有限公司 | I9: 10655.1 | J9: 10655.1 | K9: 杂质超标 | L9: YMFJZZ250142 | M9: 福建经营部 | N9: 饲料原料部 | O9: 陈静文 | P9: 福建经营部 | Q9: 大区品种线 | Y9: =YEAR(C9) -> 2025 | Z9: =MONTH(C9) -> 8 | AA9: =DAY(C9) -> 20
A10: YMFJZZ250173-lxd01 | B10: 45889 | C10: 45889 | D10: 商务扣款 | E10: 正大原料供应有限公司 | I10: 4698.52 | J10: 4698.52 | K10: 杂质和破碎超标 | L10: YMFJZZ250173 | M10: 福建经营部 | N10: 饲料原料部 | O10: 陈静文 | P10: 福建经营部 | Q10: 大区品种线 | Y10: =YEAR(C10) -> 2025 | Z10: =MONTH(C10) -> 8 | AA10: =DAY(C10) -> 20
A11: YMFJZZ250130-lxd01 | B11: 45888 | C11: 45888 | D11: 商务扣款 | E11: 漳州海大饲料有限公司 | I11: 936 | J11: 936 | K11: 杂质超标 | L11: YMFJZZ250130 | M11: 福建经营部 | N11: 饲料原料部 | O11: 陈静文 | P11: 福建经营部 | Q11: 大区品种线 | Y11: =YEAR(C11) -> 2025 | Z11: =MONTH(C11) -> 8 | AA11: =DAY(C11) -> 19
A12: YHSZFJ250613XMX0001-lxd01 | B12: 45888 | C12: 45888 | D12: 商务扣款 | E12: 四川新希望贸易有限公司 | I12: 311.4 | J12: 311.4 | K12: 容重不达标 | L12: YHSZFJ250613XMX0001 | M12: 福建经营部 | N12: 饲料原料部 | O12: 陈静文 | P12: 福建经营部 | Q12: 大区品种线 | Y12: =YEAR(C12) -> 2025 | Z12: =MONTH(C12) -> 8 | AA12: =DAY(C12) -> 19
A13: YMZSJJY250170 | B13: 46001 | C13: 46002 | D13: 商务扣款 | E13: 丰顺县海新饲料有限公司 | F13: 丰顺县海新饲料有限公司，2025年11月12日签订《粮食销售合同(赊销)》(合同编号:YMZSJJY250170)，数量 500 吨，单价 2320 元/吨，该合同已累计交货 496吨，(其中 11月 20日3 车车号:赣 C5615D，重量 31.7吨，车号:粤 V05263,重量 33.77 吨，车号:粤 VN1708，重量 34.84吨，合计:100.31 吨)到货玉米经检验杂质 1.2%杂质和破碎粒超出合同约定指标(杂质≤1%),不符合客户接受指标。针对该批次到厂不合格玉米，经双方友好协商处理后，退货转扣款接收。经双方友好协商处理后，退货转扣款接收，合计扣款 1003.1元 折合10元/吨。 | H13: 品质不达标（容重、水分、毒素、蛋白等） | I13: 1003.1 | J13: 100.31 | K13: 恒通达/2529、锦航力鹏/2528 | L13: YMZSJJY250170 | M13: 珠三角经营部 | N13: 饲料原料部 | O13: 蚁毓霖 | P13: 珠三角经营部 | Q13: 大区品种线 | Y13: =YEAR(C13) -> 2025 | Z13: =MONTH(C13) -> 12 | AA13: =DAY(C13) -> 11
A14: YMZSIIY250177 | B14: 46001 | C14: 46002 | D14: 商务扣款 | E14: 丰顺县海新饲料有限公司 | F14: 丰顺县海新饲料有限公司,于2025年11月20日签订《粮食销售合同》(合同编号:YMZSIIY250177)，数量 500 吨，单价 2340 元/吨,该合同已累计交货 495.46吨，(其中12月2日4车车号:粤 BGT302,重量 34.97 吨，车号:赣C4M573，重量 36.5吨，车号:粤D28948，重量 38.6吨，车号:赣C7N367,重量 43.52 吨合计:153.59 吨)到货玉米经检验杂质 1.2%杂质和破碎粒超出合同约定指标(杂质≤19)，不符合客户接受指标。针对该批次到厂不合格玉米，经双方友好协商处理后，退货转扣款接收。 | H14: 品质不达标（容重、水分、毒素、蛋白等） | I14: 1535.9 | J14: 153.59 | K14: 鑫顺弘盛/2537 | L14: YMZSIIY250177 | M14: 珠三角经营部 | N14: 饲料原料部 | O14: 蚁毓霖 | P14: 珠三角经营部 | Q14: 大区品种线 | Y14: =YEAR(C14) -> 2025 | Z14: =MONTH(C14) -> 12 | AA14: =DAY(C14) -> 11
A15: JZXYMZSJJM25047 玉米扣款—保险 | B15: 45925 | C15: 46000 | D15: 商务扣款 | E15: 广东粮品农产品经验有限公司 | F15: 经双方友好协商处理后，退货转扣款接收，合计扣款 1535.9元 折合10 元/吨。 | H15: 包装破损、水湿、短重等 | I15: 23574.6 | J15: 46.19 | K15: 箱子进水 | L15: JZXYMZSJJM25047 | M15: 珠三角经营部 | N15: 饲料原料部 | O15: 汤妮 | P15: 珠三角经营部 | Q15: 大区品种线 | Y15: =YEAR(C15) -> 2025 | Z15: =MONTH(C15) -> 12 | AA15: =DAY(C15) -> 9
A16: JZXYMZSJJM25047 玉米扣款 | B16: 45925 | C16: 46000 | D16: 商务扣款 | E16: 广东粮品农产品经验有限公司 | F16: 广东粮品农产品经验有限公司，于2025 年9月25 日签订的《粮食销售合同》合同编号:JZXYMZSJJM25047)合同数量 351 吨,合同单价 2460 元/吨，计划号 YHSZ-25-072128，运单号 AYWWCRX250607901A，共13 柜，截止到9月 29 日该合同下货物已提货完毕。其中 6柜玉米分别存在霉变和生虫的现象: (1)TAHU1162503和ATHU1046083，26.73和7.78，霉变超标，扣款 50 元/吨 (2)ATHU1046083、ATHU1265939、ATHU1303556、ATHU1246651和ATHU1103202卸重分别为 26.86、26.85、26.9和 27.21，存在生虫现象，扣款 50 元/吨合计扣款金额为:7965.9元。 | H16: 质量问题（霉变、霉味、生虫等） | I16: 7965.9 | J16: 142.33 | L16: JZXYMZSJJM25047 | M16: 珠三角经营部 | N16: 饲料原料部 | O16: 汤妮 | P16: 珠三角经营部 | Q16: 大区品种线 | Y16: =YEAR(C16) -> 2025 | Z16: =MONTH(C16) -> 12 | AA16: =DAY(C16) -> 9
A17: YMZSJQY250219 | B17: 45980 | C17: 46002 | D17: 商务扣款 | E17: 广东泰德饲料有限公司扣款 | F17: 广东泰德饲料有限公司于11月12日签订国产内贸合同(合同号YMZSJQY250219，合同量1000 吨，单价 2320 元/吨)，该合同为吉林经营部与我司珠三角经营部协同发往英德站的保1000 毒素玉米，客户于 11月19 日开始提货其中，有6车玉米呕吐毒素超出合同第二条:质量标准中:呕吐毒素<1000ug/kg的约定，具体明细如下:经过双方友好协商，决定对该批次不合格的玉米进行扣款处理，经沟通，毒素超示的部分扣款一共 5451.6 元由上游吉林经营部承担。 | H17: 质量问题（霉变、霉味、生虫等） | I17: 5451.6 | K17: 吉林经营部发运 | L17: YMZSJQY250219 | M17: 珠三角经营部 | N17: 饲料原料部 | O17: 董典昊 | P17: 珠三角经营部 | Q17: 大区品种线 | Y17: =YEAR(C17) -> 2025 | Z17: =MONTH(C17) -> 12 | AA17: =DAY(C17) -> 11
A18: YMZSJQY250205 | B18: 45982 | C18: 46002 | D18: 商务扣款 | E18: 郴州大北农饲料有限公司扣款 | F18: 郴州大北农饲料科技有限公司于 11月11日签订国产内贸合同(合同号YMZSJQY250205，合同量 800 吨，单价 2250 元/吨)，客户于 11月21 日开始提货我司麻涌港:国家能源 610/2511 轮玉米，现有部分玉米到厂后，出现杂质超标情况，明细如下:除湘 LB8781 提货杂质为 1.19%扣款 10 元/吨外，其余车辆杂质综合达到2.21%，该合同第二条质量标准约定:杂质≤1.0%，经过双方友好协商，决定对该批次不合格的玉米进行扣款处理，请领导审批。经沟通，该批次货物扣款共计:6649元。 | H18: 质量问题（霉变、霉味、生虫等） | I18: 6649 | K18: 国家能源 610/2511 | L18: YMZSJQY250205 | M18: 珠三角经营部 | N18: 饲料原料部 | O18: 董典昊 | P18: 珠三角经营部 | Q18: 大区品种线 | Y18: =YEAR(C18) -> 2025 | Z18: =MONTH(C18) -> 12 | AA18: =DAY(C18) -> 11
A19: YMZSJQY250179 | B19: 45985 | C19: 46002 | D19: 商务扣款 | E19: 英德天农饲料有限公司扣款 | F19: 英德天农饲料有限公司，2025 年11月15日签订的《粮食销售合同》(合同编号:YMZSJQY250179)合同数量 1000 吨，合同单价 2310 元/吨，根据签订的《粮食销售合同》第二条款约定的质量标准，交付的玉米标准应当符合如下约定:“容重2685g儿L，水分≤15.0%，杂质≤1.0%，霉变粒≤2.0%，呕吐毒素≤1000ug/kg，”。客户提货我司从北方发运散改基玉米，2025年11月16日至24日到厂柜号:5588171、0809541、330766、6457540、0733826，共受委托承运供方玉米 120.01 吨，合同单价 2310 元/吨，到需方英德天农工厂，经品管技术部门抽样不达合同约定标准，经供需双方友好协商，需方同意2车玉米折价收货。其中 5588171、0809541柜毒素超标:1493.99、1147.01，双方友好协商折价 30元/吨，结算即 2280 元/吨为准;330766柜毒素超标:1081.93，双方友好协商折价5元/吨，结算即 2305 元/吨为准;6457540、0733826柜毒素超标:1066.21、1024.4，双方友好协商折价5元/吨，结算即 2305 元/吨为准。合计扣款1344.8元 | H19: 质量问题（霉变、霉味、生虫等） | I19: 1344.8 | K19: 吉林经营部发运 | L19: YMZSJQY250179 | M19: 珠三角经营部 | N19: 饲料原料部 | O19: 董典昊 | P19: 珠三角经营部 | Q19: 大区品种线 | Y19: =YEAR(C19) -> 2025 | Z19: =MONTH(C19) -> 12 | AA19: =DAY(C19) -> 11
A20: JCYMZSJQY250029-1 | B20: 45988 | C20: 46020 | D20: 商务扣款 | E20: 关于安佑集团结算扣价 | F20: 苏州穗满德国际贸易有限公司，2025年11月13日签订的《粮食销售合同》(合同编号:JCYMZSJQY250029-1)合同数量1500吨，合同单价2302元/吨，提货新沙港国远86、中瑞祥79，三车到厂检测霉变为2.5%超出合同约定的标准，合计98.38吨，申请每吨扣款20元，扣款20元*98.38吨=1967.6元。 | H20: 品质不达标（容重、水分、毒素、蛋白等） | I20: 1967.6 | J20: 98.38 | K20: 国远86、中瑞祥79 | L20: JCYMZSJQY250029-1 | M20: 珠三角经营部 | N20: 饲料原料部 | O20: 董典昊 | Y20: =YEAR(C20) -> 2025 | Z20: =MONTH(C20) -> 12 | AA20: =DAY(C20) -> 29
A21: YMYXMM250768 | B21: 45979 | C21: 46002 | D21: 商务扣款 | E21: 双胞胎（集团）股份有限公司扣款 | F21: 客户在对应外采船“锦富航 69/2530”轮提货过程中，反馈 706.74 吨玉米感官有黑粒，霉变超标，存在质量不合格问题，经饲料厂人员取样检测并复查，霉变达 2.3%，合同约定质量标准：霉变粒≤2%，不符合合同规定。经我部与客 户多次协商，秉承长期友好合同原则，共申请扣款 14134.8 元，单吨扣款 20 元/吨 | H21: 质量问题（霉变、霉味、生虫等） | I21: 14134.8 | J21: 706.74 | K21: 锦富航 69/2530 | L21: YMYXMM250768 | M21: 粤西经营部 | N21: 饲料原料部 | O21: 余诗莹 | P21: 饲料原料部 | Q21: 大区品种线 | Y21: =YEAR(C21) -> 2025 | Z21: =MONTH(C21) -> 12 | AA21: =DAY(C21) -> 11
A22: 关于JZXYMZSJJM25048玉米扣款 | B22: 45933 | C22: 46002 | D22: 商务扣款 | E22: 鹤山市广顺饲料有限公司 | F22: 鹤山市广顺饲料有限公司，于 2025 年 09 月 28 日签订的《粮食销售合同》合同编号:JZXYMZSJJM25048)合同数量 150 吨,合同单价 2400 元/吨，计划号JZXYMSZCG250076 和YHSZ-25-072128，运单号Q085591683和AYWWCRX250607901A，共6柜，截止到 10月 3日该合同下货物已提货完毕。 1、柜号 XYLU1060398，卸厂数 26.42 吨，水湿发霉，发热结块严重，价格按 1700 元/吨结算，已报保险，保险承担8800元。 2、柜号 00CU0908616和 ATHU1168857,卸厂数分别为 26.403和 9.9(半柜)，发热发霉价格按 2330 元/吨结算，其中00CU0908616已报保险，保险承担9920元。合计扣款金额为:18494+2541.21=21035.21元，已报保险，保险承担18720元. | H22: 包装破损、水湿、短重等 | I22: 21035.21 | J22: 62.723 | L22: JZXYMZSJJM25048 | M22: 珠三角经营部 | N22: 饲料原料部 | O22: 汤妮 | P22: 珠三角经营部 | Q22: 大区品种线 | Y22: =YEAR(C22) -> 2025 | Z22: =MONTH(C22) -> 12 | AA22: =DAY(C22) -> 11
A23: YMYXYJ250166 | B23: 46002 | C23: 46002 | D23: 商务扣款 | E23: 阳江双胞胎饲料有限公司 | F23: 我司于2025年9月18日与阳江双胞胎饲料有限公司签订了玉米内贸合同YMYXYJ250166，签订主体为中粮贸易（深圳）有限公司。合同总量为1000吨，单价为2440元/吨，实际执行量为949.18吨。具体提货情况如下：在锦航万盛/2522船上提货473.68吨，在鑫晟奋发/2523船上提货475.50吨。合同约定标准：呕吐毒素含量不得超过1000PPB。 在2025年9月21日至2025年10月9日期间，客户提取了一批玉米（猪料），经检测，呕吐毒素含量在1131至1452之间，不符合合同约定的标准。考虑到双方后期的长期友好合作，对该批货物进行20元/吨的折价处理，总计折价金额为18938.6元。此次扣款已从预留的20000元中扣除。 | H23: 品质不达标（容重、水分、毒素、蛋白等） | I23: 18983.6 | J23: 949.18 | K23: 鑫晟奋发/2523、锦航万盛/2522 | L23: YMYXYJ250166 | M23: 粤西经营部 | N23: 饲料原料部 | O23: 刘佳莹 | P23: 饲料原料部 | Q23: 大区品种线 | Y23: =YEAR(C23) -> 2025 | Z23: =MONTH(C23) -> 12 | AA23: =DAY(C23) -> 11
A24: 茂名海航 YMYXMM250260 质量扣款的情况说明 | B24: 45895 | C24: 45988 | D24: 商务扣款 | E24: 茂名海航饲料有限公司 | F24: 在外采大船“天台 19/2518”轮提货过程中，160.05 吨存在有异常发热、有霉味、杂质超标的质量问题，杂 质达 3.7%，不符合同规定。经我司业务人员核实，检测结果确实存在。秉承长期友好合同原则，经我部与客 户多次友好协商后，做扣价 30 元/吨处理，申请扣款金额合计 4801.5 元，该船质量问题已报备饲料原料部。 由于该合同已经结算，申请在 YMYXMM250747 做抵扣 | H24: 品质不达标（容重、水分、毒素、蛋白等） | I24: 4801.5 | J24: 160.05 | K24: 天台 19/2518 | L24: YMYXMM250260 | M24: 粤西经营部 | N24: 饲料原料部 | O24: 余诗莹 | P24: 饲料原料部 | Q24: 大区品种线 | Y24: =YEAR(C24) -> 2025 | Z24: =MONTH(C24) -> 11 | AA24: =DAY(C24) -> 27
A25: YMFJFZ250147 | B25: 40703 | C25: 46000 | D25: 商务扣款 | E25: 双胞胎（集团）股份有限公司 | F25: 兹有我司与双胞胎（集团）股份有限公司签订《粮食销售合同》（合同号：YMFJFZ250147）合同数量1000吨，单价2310元/吨，合同约定呕吐毒素≤1000ppb。该合同实际接货1019.74吨，在提货过程中,出现部分车次呕吐毒素超标问题,扣款金额为 5264.4元,折合5.16元/吨。该批次提货对应军航码头散船瑞生16/2528轮（挑选出货），该批次销售为双胞胎集团下属工厂屏南双胞胎饲料有限公司，为首次开发工厂，客户扣款已在后续合同中以保毒素玉米价格加价给我司（YMFJFZ250188合同，1000吨，2425元/吨，加价16元/吨）。 | Y25: =YEAR(C25) -> 2025 | Z25: =MONTH(C25) -> 12 | AA25: =DAY(C25) -> 9
A26: YMFJZZ250287 | B26: 45983 | C26: 46005 | D26: 商务扣款 | E26: 福建湘大骆驼饲料有限公司 | Y26: =YEAR(C26) -> 2025 | Z26: =MONTH(C26) -> 12 | AA26: =DAY(C26) -> 14
A27: JZXYMGXXJ250067 | B27: 45975 | C27: 46005 | D27: 商务扣款 | E27: 广西南宁央卓粮食贸易有限公司 | F27: 客户名：广西南宁央卓粮食贸易有限公司,合同号：JZXYMGXXJ250067,单价：2275元/吨，签订指标：容重 ≥710g/l，水分≤14.5%，霉变≤2%，热损≤1%，杂质≤1%，不完善≤8%，呕吐毒素≤1000ppb，计划号： YHSZ-25-092334，运单号：AWKTRTT250772047、APSFCQC250784002，11月14日开始提货，在交货时， 下反馈毒素超标，经我放人员核实并重新取样邮寄至北良华正检测（检测结果如附件），客户反馈共计16柜（444.08吨）毒素超标，每吨扣款60元/吨，经我部与客户多次友好协商后，对其中14 柜（389.55吨）做扣价 20 元/吨处理，即本合同扣款389.55吨*20元/吨=7791元， | H27: 品质不达标（容重、水分、毒素、蛋白等） | I27: 7791 | J27: 389.55 | L27: JZXYMGXXJ250067 | M27: 广西经营部 | N27: 饲料原料部 | O27: 朱雪语 | Y27: =YEAR(C27) -> 2025 | Z27: =MONTH(C27) -> 12 | AA27: =DAY(C27) -> 14
A28: YHYMGXXS250904003 | B28: 9月13 | C28: 46006 | D28: 商务扣款 | E28: 广西柳州桂柳牧业有限公司 | F28: 合同号：YHYMGXXS250904003，客户名：广西柳州桂柳牧业有限公司，合同数量：700吨，单价：2390元/ 吨 , 提货数量：692.22吨，该批粮源为扬翔退货货源，在发运时，船运已反馈杂质大、破碎高，到达白沙港 时，我部人员朱雪语，现场检查，情况属实，并伴有发霉发热现场。退回白沙库（提珠三角“国远705”船，驳 船名：贵港兴泰82）另行销售，在销售时按照市场行情正价销售，于9月5日-9月13日陆续提货，到厂收货时，客 户反馈其中472.15吨出现发霉，发热等现象，客户提出该部分每吨扣款60元接收，经过跟客户友好协商，每吨按 照30元进行扣款让步接收，即472.15元*30元/吨=14,164.5元 | H28: 质量问题（霉变、霉味、生虫等） | I28: 14164.5 | J28: 472.15 | K28: 国远705 | L28: YHYMGXXS250904003 | M28: 广西经营部 | N28: 饲料原料部 | O28: 朱雪语 | Y28: =YEAR(C28) -> 2025 | Z28: =MONTH(C28) -> 12 | AA28: =DAY(C28) -> 15
A29: YMZSJDG250122 | B29: 45867 | C29: 46006 | D29: 商务扣款 | E29: 广州顺泽粮食贸易有限公司 | F29: 一体化计划号:YHSZ-25-062402，YHSZ-25-062403，YHSZ-25-062404共销售广州顺泽粮食贸易有限公司115 柜，2025年7月11日签订的《粮食销售合同》(合同编号:YMZSJDG250122)合同数量 3000吨，合同单价 2440 元/吨，结算数量 3054.678 吨。该合同交货过程中 102 柜质量问题产生扣款合计扣款91846.45 元: 其中 82 柜发热有霉味扣款 30 元/吨让步降价处理;1柜发热发霉结块扣款 80 元/吨让步接收，1 柜箱内有垃圾，水湿结块，扣款 40 元/吨降价处理,1柜发热发霉,有虫扣款 60 元/吨让步接收,1柜容重 702ppb复测 696ppb,不达标扣款 10 元/吨，1柜容重 695ppb 不达标扣款 20 元/吨。 | H29: 发霉发热 | I29: 91846.45 | K29: 天隆河/299S、延展228/043S、昌盛集 9/047S | L29: YMZSJDG250122 | M29: 珠三角经营部 | N29: 饲料原料部 | O29: 林佳琦 | Y29: =YEAR(C29) -> 2025 | Z29: =MONTH(C29) -> 12 | AA29: =DAY(C29) -> 15
B30: 46001 | C30: 46006 | D30: 商务扣款 | E30: 关于南宁海大杂质超标扣款 | F30: 在珠三角提货，因交货为筒仓货物，交货时均为筒仓底部货物，杂质偏大 | H30: 杂质超标 | I30: 29949.34 | J30: 2994.934 | K30: 东星海泰/077 | L30: /YMGXQZ250275/YMGXQZ250276 | M30: 广西经营部 | N30: 饲料原料部 | O30: 宁昕 | Y30: =YEAR(C30) -> 2025 | Z30: =MONTH(C30) -> 12 | AA30: =DAY(C30) -> 15
A31: YHYMZSJXS251113002 | B31: 45987 | C31: 46006 | D31: 商务扣款 | E31: 广州顺泽粮食贸易有限公司 | F31: 该合同交货过程中1柜箱号:OOLU2987138 箱底未干0.3 吨粘底卸不下来客户折价 1732 元/吨，扣款 519.6 元让步接收 | H31: 质量问题（水湿粘底） | I31: 519.6 | J31: 0.3 | K31: TIAN XIU HE 340S | L31: YHYMZSJXS251113002 | M31: 珠三角经营部 | N31: 饲料原料部 | O31: 林佳琦 | Y31: =YEAR(C31) -> 2025 | Z31: =MONTH(C31) -> 12 | AA31: =DAY(C31) -> 15
A32: YMYXMM250558 | B32: 45943 | C32: 46006 | D32: 商务扣款 | E32: 关于潘钟明、余剑玲、黄东宇、林雪清、许忠炯、广东双谷、双胞胎陈粮合同折价的情况说明 | F32: 因无陈粮库存交货，经多次反复沟通协商，以下打包厂、饲料厂陈粮合同剩余未提量在”佳升56/2521“、“锦江河/2519”、“海腾炜业6/2508”、“锦江河/2521”、“利泰朝阳/2524”新船执行，申请在新船执行量折价30元/吨，以下为具体明细 | H32: 品质不达标（容重、水分、毒素、蛋白等） | I32: 9482.4 | J32: 316.08 | K32: 佳升56/2521 | L32: YMYXMM250558 | M32: 粤西经营部 | N32: 饲料原料部 | O32: 余诗莹 | P32: 饲料原料部 | Q32: 大区品种线 | Y32: =YEAR(C32) -> 2025 | Z32: =MONTH(C32) -> 12 | AA32: =DAY(C32) -> 15
A33: YMYXMM250554 | B33: 45943 | C33: 46006 | D33: 商务扣款 | E33: 关于潘钟明、余剑玲、黄东宇、林雪清、许忠炯、广东双谷、双胞胎陈粮合同折价的情况说明 | F33: 因无陈粮库存交货，经多次反复沟通协商，以下打包厂、饲料厂陈粮合同剩余未提量在”佳升56/2521“、“锦江河/2519”、“海腾炜业6/2508”、“锦江河/2521”、“利泰朝阳/2524”新船执行，申请在新船执行量折价30元/吨，以下为具体明细 | H33: 品质不达标（容重、水分、毒素、蛋白等） | I33: 7481.1 | J33: 249.37 | K33: 佳升56/2521 | L33: YMYXMM250554 | M33: 粤西经营部 | N33: 饲料原料部 | O33: 余诗莹 | P33: 饲料原料部 | Q33: 大区品种线 | Y33: =YEAR(C33) -> 2025 | Z33: =MONTH(C33) -> 12 | AA33: =DAY(C33) -> 15
A34: YMYXMM250602 | B34: 45947 | C34: 46006 | D34: 商务扣款 | E34: 关于潘钟明、余剑玲、黄东宇、林雪清、许忠炯、广东双谷、双胞胎陈粮合同折价的情况说明 | F34: 因无陈粮库存交货，经多次反复沟通协商，以下打包厂、饲料厂陈粮合同剩余未提量在”佳升56/2521“、“锦江河/2519”、“海腾炜业6/2508”、“锦江河/2521”、“利泰朝阳/2524”新船执行，申请在新船执行量折价30元/吨，以下为具体明细 | H34: 品质不达标（容重、水分、毒素、蛋白等） | I34: 14221.2 | J34: 474.04 | K34: 佳升56/2521、锦江河/2519、海腾炜业6/2508、锦江河/2521、利泰朝阳/2524 | L34: YMYXMM250602 | M34: 粤西经营部 | N34: 饲料原料部 | O34: 余诗莹 | P34: 饲料原料部 | Q34: 大区品种线 | Y34: =YEAR(C34) -> 2025 | Z34: =MONTH(C34) -> 12 | AA34: =DAY(C34) -> 15
A35: YMYXMM250553 | B35: 45943 | C35: 46006 | D35: 商务扣款 | E35: 关于潘钟明、余剑玲、黄东宇、林雪清、许忠炯、广东双谷、双胞胎陈粮合同折价的情况说明 | F35: 因无陈粮库存交货，经多次反复沟通协商，以下打包厂、饲料厂陈粮合同剩余未提量在”佳升56/2521“、“锦江河/2519”、“海腾炜业6/2508”、“锦江河/2521”、“利泰朝阳/2524”新船执行，申请在新船执行量折价30元/吨，以下为具体明细 | H35: 品质不达标（容重、水分、毒素、蛋白等） | I35: 8663.4 | J35: 288.78 | K35: 佳升56/2521、锦江河/2519 | L35: YMYXMM250553 | M35: 粤西经营部 | N35: 饲料原料部 | O35: 余诗莹 | P35: 饲料原料部 | Q35: 大区品种线 | Y35: =YEAR(C35) -> 2025 | Z35: =MONTH(C35) -> 12 | AA35: =DAY(C35) -> 15
A36: YMYXMM250596 | B36: 45950 | C36: 46006 | D36: 商务扣款 | E36: 关于潘钟明、余剑玲、黄东宇、林雪清、许忠炯、广东双谷、双胞胎陈粮合同折价的情况说明 | F36: 因无陈粮库存交货，经多次反复沟通协商，以下打包厂、饲料厂陈粮合同剩余未提量在”佳升56/2521“、“锦江河/2519”、“海腾炜业6/2508”、“锦江河/2521”、“利泰朝阳/2524”新船执行，申请在新船执行量折价30元/吨，以下为具体明细 | H36: 品质不达标（容重、水分、毒素、蛋白等） | I36: 14747.1 | J36: 491.57 | K36: 锦江河/2519 | L36: YMYXMM250596 | M36: 粤西经营部 | N36: 饲料原料部 | O36: 余诗莹 | P36: 饲料原料部 | Q36: 大区品种线 | Y36: =YEAR(C36) -> 2025 | Z36: =MONTH(C36) -> 12 | AA36: =DAY(C36) -> 15
A37: YMYXMM250582 | B37: 45943 | C37: 46006 | D37: 商务扣款 | E37: 关于潘钟明、余剑玲、黄东宇、林雪清、许忠炯、广东双谷、双胞胎陈粮合同折价的情况说明 | F37: 因无陈粮库存交货，经多次反复沟通协商，以下打包厂、饲料厂陈粮合同剩余未提量在”佳升56/2521“、“锦江河/2519”、“海腾炜业6/2508”、“锦江河/2521”、“利泰朝阳/2524”新船执行，申请在新船执行量折价30元/吨，以下为具体明细 | H37: 品质不达标（容重、水分、毒素、蛋白等） | I37: 11266.2 | J37: 375.54 | K37: 佳升56/2521 | L37: YMYXMM250582 | M37: 粤西经营部 | N37: 饲料原料部 | O37: 余诗莹 | P37: 饲料原料部 | Q37: 大区品种线 | Y37: =YEAR(C37) -> 2025 | Z37: =MONTH(C37) -> 12 | AA37: =DAY(C37) -> 15
A38: YMYXMM250569 | B38: 45943 | C38: 46006 | D38: 商务扣款 | E38: 关于潘钟明、余剑玲、黄东宇、林雪清、许忠炯、广东双谷、双胞胎陈粮合同折价的情况说明 | F38: 因无陈粮库存交货，经多次反复沟通协商，以下打包厂、饲料厂陈粮合同剩余未提量在”佳升56/2521“、“锦江河/2519”、“海腾炜业6/2508”、“锦江河/2521”、“利泰朝阳/2524”新船执行，申请在新船执行量折价30元/吨，以下为具体明细 | H38: 品质不达标（容重、水分、毒素、蛋白等） | I38: 4800 | J38: 160 | K38: 佳升56/2521 | L38: YMYXMM250569 | M38: 粤西经营部 | N38: 饲料原料部 | O38: 余诗莹 | P38: 饲料原料部 | Q38: 大区品种线 | Y38: =YEAR(C38) -> 2025 | Z38: =MONTH(C38) -> 12 | AA38: =DAY(C38) -> 15
A39: YMYXMM250564 | B39: 45943 | C39: 46006 | D39: 商务扣款 | E39: 关于潘钟明、余剑玲、黄东宇、林雪清、许忠炯、广东双谷、双胞胎陈粮合同折价的情况说明 | F39: 因无陈粮库存交货，经多次反复沟通协商，以下打包厂、饲料厂陈粮合同剩余未提量在”佳升56/2521“、“锦江河/2519”、“海腾炜业6/2508”、“锦江河/2521”、“利泰朝阳/2524”新船执行，申请在新船执行量折价30元/吨，以下为具体明细 | H39: 品质不达标（容重、水分、毒素、蛋白等） | I39: 12204 | J39: 406.8 | K39: 佳升56/2521 | L39: YMYXMM250564 | M39: 粤西经营部 | N39: 饲料原料部 | O39: 余诗莹 | P39: 饲料原料部 | Q39: 大区品种线 | Y39: =YEAR(C39) -> 2025 | Z39: =MONTH(C39) -> 12 | AA39: =DAY(C39) -> 15
A40: YMYXMM250576 | B40: 45943 | C40: 46006 | D40: 商务扣款 | E40: 关于潘钟明、余剑玲、黄东宇、林雪清、许忠炯、广东双谷、双胞胎陈粮合同折价的情况说明 | F40: 因无陈粮库存交货，经多次反复沟通协商，以下打包厂、饲料厂陈粮合同剩余未提量在”佳升56/2521“、“锦江河/2519”、“海腾炜业6/2508”、“锦江河/2521”、“利泰朝阳/2524”新船执行，申请在新船执行量折价30元/吨，以下为具体明细 | H40: 品质不达标（容重、水分、毒素、蛋白等） | I40: 14578.5 | J40: 485.95 | K40: 锦江河/2519 | L40: YMYXMM250576 | M40: 粤西经营部 | N40: 饲料原料部 | O40: 余诗莹 | P40: 饲料原料部 | Q40: 大区品种线 | Y40: =YEAR(C40) -> 2025 | Z40: =MONTH(C40) -> 12 | AA40: =DAY(C40) -> 15
...

Sheet 联系单模版
A1: 联系单编号： | B1: JZXYMZSJJM26001
A2: 中粮贸易沿海大区工作联系单
A3: 发出部门 | B3: =VLOOKUP(B1,流程!A:O,12,FALSE) -> JZXYMZSJJM26001 | D3: 接收部门 | E3: =VLOOKUP(B1,流程!A:P,13,FALSE) -> 珠三角经营部
A4: 主题 | B4: =VLOOKUP(B1,流程!A:G,5,FALSE) -> 关于开平市绿皇JZXYMZSJJM26001合同商务扣款
A5: =VLOOKUP(B1,流程!A:H,6,FALSE) -> YHSZ-25-121919、开平市绿皇农牧发展有限公司，2026年1月6日签订的《粮食销售合同》（合同编号：JZXYMZSJJM26001）合同数量1030吨，合同单价2450元/吨，结算数量1018.14，其中3柜，总共76.53吨，因工厂仓库收货开柜后发现玉米有霉味的现象，经过协商沟通，进行扣款处理。（1）车号:湘U6955,柜号:XYLU1191171，来货实收重量:21.55吨。（2）车号:湘MJ9132,柜号:XYLU1178631，来货实收重量:27.98吨。（3）车号:湘LD6811,柜号:XYLU1313449，来货实收重量:27吨。合计:76.53*20=1530.6元
A6: 发起人 | C6: =VLOOKUP(B1,流程!A:R,15,FALSE) -> 汤妮 | E6: =VLOOKUP(B1,流程!A:S,16,FALSE) -> 珠三角经营部

Sheet 字段列表
A2: 费用原因分类
A3: 质量问题（霉变、霉味、生虫等）
A4: 物流发运与计划不符
A5: 发运集中到货
A6: 库存前移未及时销售
A7: 流程手续问题
A8: 客户仓容有限提货慢
A9: 包装破损、水湿、短重等
A10: 品质不达标（容重、水分、毒素、蛋白等）
A11: 其他原因
